[2020-05-22 14-14-04] [INFO] +-+-+-+-+-+-+- Inicio Proceso Principal ! +-+-+-+-+-+-+-
[2020-05-22 14-14-04] [INFO] Intento de conexion #0
[2020-05-22 14-14-19] [INFO] Conexion Establecida 15 s
[2020-05-22 14-14-19] [INFO] +-+-+-+-+-+-+- Inicio Proceso canales_itc! +-+-+-+-+-+-+-
[2020-05-22 14-14-31] [ERROR] Error en Ejecución de canales_itc fallido
[2020-05-22 14-14-31] [ERROR] Tipo de Excepcion : ConnectionError
[2020-05-22 14-14-31] [ERROR] Mensaje : ('Connection aborted.', RemoteDisconnected('Remote end closed connection without response'))
[2020-05-22 14-14-31] [ERROR] Stack trace : ['File : C:\\Users\\Willson\\Downloads\\UdeA\\Practicas\\Bancolombia\\Canales\\GIT\\canales-bancolombia-master\\canales.py , Line : 215, Func.Name : main, Message : datelist = listDatesfromUltimateIngestion(bucketFolder,log)', "File : C:\\Users\\Willson\\Downloads\\UdeA\\Practicas\\Bancolombia\\Canales\\GIT\\canales-bancolombia-master\\canales.py , Line : 88, Func.Name : listDatesfromUltimateIngestion, Message : bucket = client.get_bucket('canales_bookmarks')", 'File : C:\\Python38\\lib\\site-packages\\google\\cloud\\storage\\client.py , Line : 333, Func.Name : get_bucket, Message : bucket.reload(client=self, timeout=timeout)', 'File : C:\\Python38\\lib\\site-packages\\google\\cloud\\storage\\_helpers.py , Line : 145, Func.Name : reload, Message : api_response = client._connection.api_request(', 'File : C:\\Python38\\lib\\site-packages\\google\\cloud\\_http.py , Line : 412, Func.Name : api_request, Message : response = self._make_request(', 'File : C:\\Python38\\lib\\site-packages\\google\\cloud\\_http.py , Line : 276, Func.Name : _make_request, Message : return self._do_request(', 'File : C:\\Python38\\lib\\site-packages\\google\\cloud\\_http.py , Line : 314, Func.Name : _do_request, Message : return self.http.request(', 'File : C:\\Python38\\lib\\site-packages\\google\\auth\\transport\\requests.py , Line : 446, Func.Name : request, Message : response = super(AuthorizedSession, self).request(', 'File : C:\\Python38\\lib\\site-packages\\requests\\sessions.py , Line : 530, Func.Name : request, Message : resp = self.send(prep, **send_kwargs)', 'File : C:\\Python38\\lib\\site-packages\\requests\\sessions.py , Line : 643, Func.Name : send, Message : r = adapter.send(request, **kwargs)', 'File : C:\\Python38\\lib\\site-packages\\requests\\adapters.py , Line : 498, Func.Name : send, Message : raise ConnectionError(err, request=request)']
[2020-05-22 14-14-31] [INFO] Ejecuciones exitosas: []
[2020-05-22 14-14-31] [INFO] Ejecuciones fallidas: []
[2020-05-22 14-14-35] [INFO] ***** Fin de Ejecución del Proceso.  Duración Total(s): 27
[2020-05-22 14-14-36] [INFO] Escribiendo log canales_itc/2020-05-22 14-05-04.txt en <Bucket: canales_logs>
